<?xml version="1.0" encoding="UTF-8"?>
<sdf version="1.6">
   <model name="my_robot_kinetic">
      <static>false</static>
      <link name="chassis">
         <pose frame="">-0 -0 0.16 0 -0 0</pose>
         <inertial>
            <mass>3.6</mass>
            <inertia>
               <ixx>0</ixx>
               <iyy>0</iyy>
               <izz>0</izz>
               <ixy>0</ixy>
               <ixz>0</ixz>
               <iyz>0</iyz>
            </inertia>
         </inertial>
         <self_collide>0</self_collide>
         <kinematic>0</kinematic>
         <visual name="castor_visual">
            <pose frame="">-0.2 0 -0.12 0 -0 0</pose>
            <geometry>
               <sphere>
                  <radius>0.04</radius>
               </sphere>
            </geometry>
            <material>
               <script>
                  <uri>file://media/materials/scripts/gazebo.material</uri>
                  <name>Gazebo/FlatBlack</name>
               </script>
               <ambient>0.1 0.1 0.1 1</ambient>
               <diffuse>0.1 0.1 0.1 1</diffuse>
               <specular>0.01 0.01 0.01 1</specular>
               <emissive>0 0 0 1</emissive>
            </material>
            <transparency>0</transparency>
            <cast_shadows>1</cast_shadows>
         </visual>
         <visual name="visual">
            <pose frame="">0 0 0.04 0 -0 0</pose>
            <geometry>
               <mesh>
                  <uri>model://pioneer2dx/meshes/chassis.dae</uri>
               </mesh>
            </geometry>
            <cast_shadows>1</cast_shadows>
            <transparency>0</transparency>
         </visual>
         <collision name="castor_collision">
            <laser_retro>0</laser_retro>
            <max_contacts>10</max_contacts>
            <pose frame="">-0.2 0 -0.12 0 -0 0</pose>
            <geometry>
               <sphere>
                  <radius>0.04</radius>
               </sphere>
            </geometry>
            <surface>
               <friction>
                  <ode>
                     <mu>0</mu>
                     <mu2>0</mu2>
                     <fdir1>0 0 0</fdir1>
                     <slip1>1</slip1>
                     <slip2>1</slip2>
                  </ode>
                  <torsional>
                     <coefficient>1</coefficient>
                     <patch_radius>0</patch_radius>
                     <surface_radius>0</surface_radius>
                     <use_patch_radius>1</use_patch_radius>
                     <ode>
                        <slip>0</slip>
                     </ode>
                  </torsional>
               </friction>
               <bounce>
                  <restitution_coefficient>0</restitution_coefficient>
                  <threshold>1e+06</threshold>
               </bounce>
               <contact>
                  <collide_without_contact>0</collide_without_contact>
                  <collide_without_contact_bitmask>1</collide_without_contact_bitmask>
                  <collide_bitmask>1</collide_bitmask>
                  <ode>
                     <soft_cfm>0</soft_cfm>
                     <soft_erp>0.2</soft_erp>
                     <kp>1e+13</kp>
                     <kd>1</kd>
                     <max_vel>0.01</max_vel>
                     <min_depth>0</min_depth>
                  </ode>
                  <bullet>
                     <split_impulse>1</split_impulse>
                     <split_impulse_penetration_threshold>-0.01</split_impulse_penetration_threshold>
                     <soft_cfm>0</soft_cfm>
                     <soft_erp>0.2</soft_erp>
                     <kp>1e+13</kp>
                     <kd>1</kd>
                  </bullet>
               </contact>
            </surface>
         </collision>
         <collision name="collision">
            <laser_retro>0</laser_retro>
            <max_contacts>10</max_contacts>
            <pose frame="">0 0 0 0 -0 0</pose>
            <geometry>
               <box>
                  <size>0.445 0.277 0.17</size>
               </box>
            </geometry>
            <surface>
               <friction>
                  <ode>
                     <mu>1</mu>
                     <mu2>1</mu2>
                     <fdir1>0 0 0</fdir1>
                     <slip1>0</slip1>
                     <slip2>0</slip2>
                  </ode>
                  <torsional>
                     <coefficient>1</coefficient>
                     <patch_radius>0</patch_radius>
                     <surface_radius>0</surface_radius>
                     <use_patch_radius>1</use_patch_radius>
                     <ode>
                        <slip>0</slip>
                     </ode>
                  </torsional>
               </friction>
               <bounce>
                  <restitution_coefficient>0</restitution_coefficient>
                  <threshold>1e+06</threshold>
               </bounce>
               <contact>
                  <collide_without_contact>0</collide_without_contact>
                  <collide_without_contact_bitmask>1</collide_without_contact_bitmask>
                  <collide_bitmask>1</collide_bitmask>
                  <ode>
                     <soft_cfm>0</soft_cfm>
                     <soft_erp>0.2</soft_erp>
                     <kp>1e+13</kp>
                     <kd>1</kd>
                     <max_vel>0.01</max_vel>
                     <min_depth>0</min_depth>
                  </ode>
                  <bullet>
                     <split_impulse>1</split_impulse>
                     <split_impulse_penetration_threshold>-0.01</split_impulse_penetration_threshold>
                     <soft_cfm>0</soft_cfm>
                     <soft_erp>0.2</soft_erp>
                     <kp>1e+13</kp>
                     <kd>1</kd>
                  </bullet>
               </contact>
            </surface>
         </collision>
      </link>
      <link name="left_wheel">
         <pose frame="">0.1 -0.17 0.11 0.000239 1.5707 1.57094</pose>
         <inertial>
            <mass>1.5</mass>
            <inertia>
               <ixx>0.0051</ixx>
               <iyy>0.0051</iyy>
               <izz>0.009</izz>
               <ixy>0</ixy>
               <ixz>0</ixz>
               <iyz>0</iyz>
            </inertia>
         </inertial>
         <self_collide>0</self_collide>
         <kinematic>0</kinematic>
         <visual name="visual">
            <geometry>
               <cylinder>
                  <radius>0.11</radius>
                  <length>0.05</length>
               </cylinder>
            </geometry>
            <material>
               <script>
                  <uri>file://media/materials/scripts/gazebo.material</uri>
                  <name>Gazebo/FlatBlack</name>
               </script>
               <ambient>0.1 0.1 0.1 1</ambient>
               <diffuse>0.1 0.1 0.1 1</diffuse>
               <specular>0.01 0.01 0.01 1</specular>
               <emissive>0 0 0 1</emissive>
            </material>
            <pose frame="">0 0 0 0 -0 0</pose>
            <transparency>0</transparency>
            <cast_shadows>1</cast_shadows>
         </visual>
         <collision name="collision">
            <laser_retro>0</laser_retro>
            <max_contacts>10</max_contacts>
            <pose frame="">0 0 0 0 -0 0</pose>
            <geometry>
               <cylinder>
                  <radius>0.11</radius>
                  <length>0.05</length>
               </cylinder>
            </geometry>
            <surface>
               <friction>
                  <ode>
                     <mu>100000</mu>
                     <mu2>100000</mu2>
                     <fdir1>0 0 0</fdir1>
                     <slip1>0</slip1>
                     <slip2>0</slip2>
                  </ode>
                  <torsional>
                     <coefficient>1</coefficient>
                     <patch_radius>0</patch_radius>
                     <surface_radius>0</surface_radius>
                     <use_patch_radius>1</use_patch_radius>
                     <ode>
                        <slip>0</slip>
                     </ode>
                  </torsional>
               </friction>
               <bounce>
                  <restitution_coefficient>0</restitution_coefficient>
                  <threshold>1e+06</threshold>
               </bounce>
               <contact>
                  <collide_without_contact>0</collide_without_contact>
                  <collide_without_contact_bitmask>1</collide_without_contact_bitmask>
                  <collide_bitmask>1</collide_bitmask>
                  <ode>
                     <soft_cfm>0</soft_cfm>
                     <soft_erp>0.2</soft_erp>
                     <kp>1e+13</kp>
                     <kd>1</kd>
                     <max_vel>0.01</max_vel>
                     <min_depth>0</min_depth>
                  </ode>
                  <bullet>
                     <split_impulse>1</split_impulse>
                     <split_impulse_penetration_threshold>-0.01</split_impulse_penetration_threshold>
                     <soft_cfm>0</soft_cfm>
                     <soft_erp>0.2</soft_erp>
                     <kp>1e+13</kp>
                     <kd>1</kd>
                  </bullet>
               </contact>
            </surface>
         </collision>
      </link>
      <link name="right_wheel">
         <pose frame="">0.1 0.17 0.11 0.000239 1.5707 1.57094</pose>
         <inertial>
            <mass>1.5</mass>
            <inertia>
               <ixx>0.0051</ixx>
               <iyy>0.0890</iyy>
               <izz>0.009</izz>
               <ixy>0</ixy>
               <ixz>0</ixz>
               <iyz>0</iyz>
            </inertia>
         </inertial>
         <self_collide>0</self_collide>
         <kinematic>0</kinematic>
         <visual name="visual">
            <geometry>
               <cylinder>
                  <radius>0.11</radius>
                  <length>0.05</length>
               </cylinder>
            </geometry>
            <material>
               <script>
                  <uri>file://media/materials/scripts/gazebo.material</uri>
                  <name>Gazebo/FlatBlack</name>
               </script>
               <ambient>0.1 0.1 0.1 1</ambient>
               <diffuse>0.1 0.1 0.1 1</diffuse>
               <specular>0.01 0.01 0.01 1</specular>
               <emissive>0 0 0 1</emissive>
            </material>
            <pose frame="">0 0 0 0 -0 0</pose>
            <transparency>0</transparency>
            <cast_shadows>1</cast_shadows>
         </visual>
         <collision name="collision">
            <laser_retro>0</laser_retro>
            <max_contacts>10</max_contacts>
            <pose frame="">0 0 0 0 -0 0</pose>
            <geometry>
               <cylinder>
                  <radius>0.11</radius>
                  <length>0.05</length>
               </cylinder>
            </geometry>
            <surface>
               <friction>
                  <ode>
                     <mu>100000</mu>
                     <mu2>100000</mu2>
                     <fdir1>0 0 0</fdir1>
                     <slip1>0</slip1>
                     <slip2>0</slip2>
                  </ode>
                  <torsional>
                     <coefficient>1</coefficient>
                     <patch_radius>0</patch_radius>
                     <surface_radius>0</surface_radius>
                     <use_patch_radius>1</use_patch_radius>
                     <ode>
                        <slip>0</slip>
                     </ode>
                  </torsional>
               </friction>
               <bounce>
                  <restitution_coefficient>0</restitution_coefficient>
                  <threshold>1e+06</threshold>
               </bounce>
               <contact>
                  <collide_without_contact>0</collide_without_contact>
                  <collide_without_contact_bitmask>1</collide_without_contact_bitmask>
                  <collide_bitmask>1</collide_bitmask>
                  <ode>
                     <soft_cfm>0</soft_cfm>
                     <soft_erp>0.2</soft_erp>
                     <kp>1e+13</kp>
                     <kd>1</kd>
                     <max_vel>0.01</max_vel>
                     <min_depth>0</min_depth>
                  </ode>
                  <bullet>
                     <split_impulse>1</split_impulse>
                     <split_impulse_penetration_threshold>-0.01</split_impulse_penetration_threshold>
                     <soft_cfm>0</soft_cfm>
                     <soft_erp>0.2</soft_erp>
                     <kp>1e+13</kp>
                     <kd>1</kd>
                  </bullet>
               </contact>
            </surface>
         </collision>
      </link>
      <joint name="left_wheel_hinge" type="revolute">
         <parent>chassis</parent>
         <child>left_wheel</child>
         <pose frame="">0 0 -0.03 0 -0 0</pose>
         <axis>
            <xyz>0 1 0</xyz>
            <use_parent_model_frame>1</use_parent_model_frame>
            <limit>
               <lower>-1e+16</lower>
               <upper>1e+16</upper>
               <effort>-1</effort>
               <velocity>-1</velocity>
            </limit>
            <dynamics>
               <spring_reference>0</spring_reference>
               <spring_stiffness>0</spring_stiffness>
               <damping>0</damping>
               <friction>0</friction>
            </dynamics>
         </axis>
         <physics>
            <ode>
               <limit>
                  <cfm>0</cfm>
                  <erp>0.2</erp>
               </limit>
               <suspension>
                  <cfm>0</cfm>
                  <erp>0.2</erp>
               </suspension>
            </ode>
         </physics>
      </joint>
      <joint name="right_wheel_hinge" type="revolute">
         <parent>chassis</parent>
         <child>right_wheel</child>
         <pose frame="">0 0 0.03 0 -0 0</pose>
         <axis>
            <xyz>0 1 0</xyz>
            <use_parent_model_frame>1</use_parent_model_frame>
            <limit>
               <lower>-1e+16</lower>
               <upper>1e+16</upper>
               <effort>-1</effort>
               <velocity>-1</velocity>
            </limit>
            <dynamics>
               <spring_reference>0</spring_reference>
               <spring_stiffness>0</spring_stiffness>
               <damping>0</damping>
               <friction>0</friction>
            </dynamics>
         </axis>
         <physics>
            <ode>
               <limit>
                  <cfm>0</cfm>
                  <erp>0.2</erp>
               </limit>
               <suspension>
                  <cfm>0</cfm>
                  <erp>0.2</erp>
               </suspension>
            </ode>
         </physics>
      </joint>
      <plugin name="differential_drive_controller" filename="libgazebo_ros_diff_drive.so">
         <alwaysOn>true</alwaysOn>
         <updateRate>20</updateRate>
         <leftJoint>left_wheel_hinge</leftJoint>
         <rightJoint>right_wheel_hinge</rightJoint>
         <wheelSeparation>0.39</wheelSeparation>
         <wheelDiameter>0.15</wheelDiameter>
         <wheelTorque>20</wheelTorque>
         <!--wheelAcceleration>5</wheelAcceleration-->
         <commandTopic>/cmd_vel</commandTopic>
         <odometryTopic>/odom</odometryTopic>
         <odometryFrame>/odom</odometryFrame>
         <publishTf>1</publishTf>
         <publishWheelJointState>true</publishWheelJointState>
         <robotBaseFrame>base_link</robotBaseFrame>
      </plugin>
      <link name="kinect_link">
         <pose frame="">0.25 0 0.40 -0 -0 -0</pose>
         <inertial>
            <mass>0.1</mass>
         </inertial>
         <collision name="collision">
            <geometry>
               <box>
                  <size>0.073000 0.276000 0.072000</size>
               </box>
            </geometry>
         </collision>
         <visual name="visual">
            <geometry>
               <mesh>
                  <uri>model://kinect/meshes/kinect.dae</uri>
               </mesh>
            </geometry>
         </visual>
         <sensor name="camera" type="depth">
            <update_rate>20</update_rate>
            <always_on>1</always_on>
            <visualize>true</visualize>
            <camera>
               <horizontal_fov>1.047198</horizontal_fov>
               <image>
                  <width>640</width>
                  <height>480</height>
                  <format>R8G8B8</format>
               </image>
               <clip>
                  <near>0.05</near>
                  <far>10</far>
               </clip>
            </camera>
            <plugin name="camera_controller" filename="libgazebo_ros_openni_kinect.so">
               <alwaysOn>true</alwaysOn>
               <updateRate>10.0</updateRate>
               <cameraName>camera</cameraName>
               <frameName>camera_link</frameName>
               <imageTopicName>rgb/image_raw</imageTopicName>
               <depthImageTopicName>depth/image_raw</depthImageTopicName>
               <pointCloudTopicName>depth/points</pointCloudTopicName>
               <cameraInfoTopicName>rgb/camera_info</cameraInfoTopicName>
               <depthImageCameraInfoTopicName>depth/camera_info</depthImageCameraInfoTopicName>
               <pointCloudCutoff>0.4</pointCloudCutoff>
               <hackBaseline>0.07</hackBaseline>
               <distortionK1>0.0</distortionK1>
               <distortionK2>0.0</distortionK2>
               <distortionK3>0.0</distortionK3>
               <distortionT1>0.0</distortionT1>
               <distortionT2>0.0</distortionT2>
               <CxPrime>0.0</CxPrime>
               <Cx>0.0</Cx>
               <Cy>0.0</Cy>
               <focalLength>0.0</focalLength>
            </plugin>
         </sensor>
      </link>
      <joint type="fixed" name="kinect_joint">
         <pose>0.15 0 0.2 0 0 0</pose>
         <child>kinect_link</child>
         <parent>chassis</parent>
         <axis>
            <xyz>0 1 0</xyz>
         </axis>
      </joint>
   </model>
</sdf>
